[2025-04-05T10:55:12.042+0000] {taskinstance.py:1979} INFO - Dependencies all met for dep_context=non-requeueable deps ti=<TaskInstance: fetch_data_and_upload_to_gcs.download_and_upload_to_gcs manual__2025-04-05T10:55:08.616153+00:00 [queued]>
[2025-04-05T10:55:12.053+0000] {taskinstance.py:1979} INFO - Dependencies all met for dep_context=requeueable deps ti=<TaskInstance: fetch_data_and_upload_to_gcs.download_and_upload_to_gcs manual__2025-04-05T10:55:08.616153+00:00 [queued]>
[2025-04-05T10:55:12.053+0000] {taskinstance.py:2193} INFO - Starting attempt 1 of 1
[2025-04-05T10:55:12.069+0000] {taskinstance.py:2214} INFO - Executing <Task(PythonOperator): download_and_upload_to_gcs> on 2025-04-05 10:55:08.616153+00:00
[2025-04-05T10:55:12.074+0000] {standard_task_runner.py:60} INFO - Started process 144 to run task
[2025-04-05T10:55:12.087+0000] {standard_task_runner.py:87} INFO - Running: ['***', 'tasks', 'run', 'fetch_data_and_upload_to_gcs', 'download_and_upload_to_gcs', 'manual__2025-04-05T10:55:08.616153+00:00', '--job-id', '11', '--raw', '--subdir', 'DAGS_FOLDER/fetch_data_and_upload_to_gcs.py', '--cfg-path', '/tmp/tmpgo4ezc1r']
[2025-04-05T10:55:12.099+0000] {standard_task_runner.py:88} INFO - Job 11: Subtask download_and_upload_to_gcs
[2025-04-05T10:55:12.229+0000] {task_command.py:423} INFO - Running <TaskInstance: fetch_data_and_upload_to_gcs.download_and_upload_to_gcs manual__2025-04-05T10:55:08.616153+00:00 [running]> on host 94ac0235f9be
[2025-04-05T10:55:12.593+0000] {taskinstance.py:2510} INFO - Exporting env vars: AIRFLOW_CTX_DAG_OWNER='***' AIRFLOW_CTX_DAG_ID='fetch_data_and_upload_to_gcs' AIRFLOW_CTX_TASK_ID='download_and_upload_to_gcs' AIRFLOW_CTX_EXECUTION_DATE='2025-04-05T10:55:08.616153+00:00' AIRFLOW_CTX_TRY_NUMBER='1' AIRFLOW_CTX_DAG_RUN_ID='manual__2025-04-05T10:55:08.616153+00:00'
[2025-04-05T10:55:13.072+0000] {connection.py:269} WARNING - Connection schemes (type: google_cloud_platform) shall not contain '_' according to RFC3986.
[2025-04-05T10:55:13.093+0000] {base.py:83} INFO - Using connection ID 'google_cloud_default' for task execution.
[2025-04-05T10:55:13.118+0000] {taskinstance.py:2728} ERROR - Task failed with exception
Traceback (most recent call last):
  File "/home/airflow/.local/lib/python3.10/site-packages/airflow/models/taskinstance.py", line 444, in _execute_task
    result = _execute_callable(context=context, **execute_callable_kwargs)
  File "/home/airflow/.local/lib/python3.10/site-packages/airflow/models/taskinstance.py", line 414, in _execute_callable
    return execute_callable(context=context, **execute_callable_kwargs)
  File "/home/airflow/.local/lib/python3.10/site-packages/airflow/operators/python.py", line 200, in execute
    return_value = self.execute_callable()
  File "/home/airflow/.local/lib/python3.10/site-packages/airflow/operators/python.py", line 217, in execute_callable
    return self.python_callable(*self.op_args, **self.op_kwargs)
  File "/opt/airflow/dags/fetch_data_and_upload_to_gcs.py", line 19, in download_and_upload_to_gcs
    hook.upload(bucket_name, destination_blob_name, temp_file.name)
  File "/home/airflow/.local/lib/python3.10/site-packages/airflow/providers/google/cloud/hooks/gcs.py", line 525, in upload
    client = self.get_conn()
  File "/home/airflow/.local/lib/python3.10/site-packages/airflow/providers/google/cloud/hooks/gcs.py", line 168, in get_conn
    credentials=self.get_credentials(), client_info=CLIENT_INFO, project=self.project_id
  File "/home/airflow/.local/lib/python3.10/site-packages/airflow/providers/google/common/hooks/base_google.py", line 307, in get_credentials
    credentials, _ = self.get_credentials_and_project_id()
  File "/home/airflow/.local/lib/python3.10/site-packages/airflow/providers/google/common/hooks/base_google.py", line 284, in get_credentials_and_project_id
    credentials, project_id = get_credentials_and_project_id(
  File "/home/airflow/.local/lib/python3.10/site-packages/airflow/providers/google/cloud/utils/credentials_provider.py", line 362, in get_credentials_and_project_id
    return _CredentialProvider(*args, **kwargs).get_credentials_and_project()
  File "/home/airflow/.local/lib/python3.10/site-packages/airflow/providers/google/cloud/utils/credentials_provider.py", line 213, in __init__
    raise AirflowException(
airflow.exceptions.AirflowException: The `keyfile_dict`, `key_path`, and `key_secret_name` fields are all mutually exclusive. Please provide only one value.
[2025-04-05T10:55:13.134+0000] {taskinstance.py:1149} INFO - Marking task as FAILED. dag_id=fetch_data_and_upload_to_gcs, task_id=download_and_upload_to_gcs, execution_date=20250405T105508, start_date=20250405T105512, end_date=20250405T105513
[2025-04-05T10:55:13.158+0000] {standard_task_runner.py:107} ERROR - Failed to execute job 11 for task download_and_upload_to_gcs (The `keyfile_dict`, `key_path`, and `key_secret_name` fields are all mutually exclusive. Please provide only one value.; 144)
[2025-04-05T10:55:13.204+0000] {local_task_job_runner.py:234} INFO - Task exited with return code 1
[2025-04-05T10:55:13.223+0000] {taskinstance.py:3309} INFO - 0 downstream tasks scheduled from follow-on schedule check
