[2025-03-23T09:03:26.725+0000] {taskinstance.py:1979} INFO - Dependencies all met for dep_context=non-requeueable deps ti=<TaskInstance: load_csv_to_bq.load_csv_to_bq manual__2025-03-23T09:03:23.694251+00:00 [queued]>
[2025-03-23T09:03:26.739+0000] {taskinstance.py:1979} INFO - Dependencies all met for dep_context=requeueable deps ti=<TaskInstance: load_csv_to_bq.load_csv_to_bq manual__2025-03-23T09:03:23.694251+00:00 [queued]>
[2025-03-23T09:03:26.740+0000] {taskinstance.py:2193} INFO - Starting attempt 1 of 1
[2025-03-23T09:03:26.753+0000] {taskinstance.py:2214} INFO - Executing <Task(GCSToBigQueryOperator): load_csv_to_bq> on 2025-03-23 09:03:23.694251+00:00
[2025-03-23T09:03:26.757+0000] {standard_task_runner.py:60} INFO - Started process 1788 to run task
[2025-03-23T09:03:26.760+0000] {standard_task_runner.py:87} INFO - Running: ['***', 'tasks', 'run', 'load_csv_to_bq', 'load_csv_to_bq', 'manual__2025-03-23T09:03:23.694251+00:00', '--job-id', '18', '--raw', '--subdir', 'DAGS_FOLDER/load_csv_to_bq.py', '--cfg-path', '/tmp/tmpqrjb8yyx']
[2025-03-23T09:03:26.761+0000] {standard_task_runner.py:88} INFO - Job 18: Subtask load_csv_to_bq
[2025-03-23T09:03:26.830+0000] {task_command.py:423} INFO - Running <TaskInstance: load_csv_to_bq.load_csv_to_bq manual__2025-03-23T09:03:23.694251+00:00 [running]> on host c0ff61c5806f
[2025-03-23T09:03:26.923+0000] {taskinstance.py:2510} INFO - Exporting env vars: AIRFLOW_CTX_DAG_OWNER='***' AIRFLOW_CTX_DAG_ID='load_csv_to_bq' AIRFLOW_CTX_TASK_ID='load_csv_to_bq' AIRFLOW_CTX_EXECUTION_DATE='2025-03-23T09:03:23.694251+00:00' AIRFLOW_CTX_TRY_NUMBER='1' AIRFLOW_CTX_DAG_RUN_ID='manual__2025-03-23T09:03:23.694251+00:00'
[2025-03-23T09:03:26.936+0000] {connection.py:269} WARNING - Connection schemes (type: google_cloud_platform) shall not contain '_' according to RFC3986.
[2025-03-23T09:03:26.944+0000] {base.py:83} INFO - Using connection ID 'google_cloud_default' for task execution.
[2025-03-23T09:03:26.945+0000] {gcs_to_bigquery.py:379} INFO - Using existing BigQuery table for storing data...
[2025-03-23T09:03:26.956+0000] {taskinstance.py:2728} ERROR - Task failed with exception
Traceback (most recent call last):
  File "/home/airflow/.local/lib/python3.8/site-packages/airflow/models/taskinstance.py", line 444, in _execute_task
    result = _execute_callable(context=context, **execute_callable_kwargs)
  File "/home/airflow/.local/lib/python3.8/site-packages/airflow/models/taskinstance.py", line 414, in _execute_callable
    return execute_callable(context=context, **execute_callable_kwargs)
  File "/home/airflow/.local/lib/python3.8/site-packages/airflow/providers/google/cloud/transfers/gcs_to_bigquery.py", line 380, in execute
    self.configuration = self._use_existing_table()
  File "/home/airflow/.local/lib/python3.8/site-packages/airflow/providers/google/cloud/transfers/gcs_to_bigquery.py", line 582, in _use_existing_table
    default_project_id=self.hook.project_id,
  File "/home/airflow/.local/lib/python3.8/site-packages/airflow/providers/google/common/hooks/base_google.py", line 372, in project_id
    _, project_id = self.get_credentials_and_project_id()
  File "/home/airflow/.local/lib/python3.8/site-packages/airflow/providers/google/common/hooks/base_google.py", line 284, in get_credentials_and_project_id
    credentials, project_id = get_credentials_and_project_id(
  File "/home/airflow/.local/lib/python3.8/site-packages/airflow/providers/google/cloud/utils/credentials_provider.py", line 362, in get_credentials_and_project_id
    return _CredentialProvider(*args, **kwargs).get_credentials_and_project()
  File "/home/airflow/.local/lib/python3.8/site-packages/airflow/providers/google/cloud/utils/credentials_provider.py", line 213, in __init__
    raise AirflowException(
airflow.exceptions.AirflowException: The `keyfile_dict`, `key_path`, and `key_secret_name` fields are all mutually exclusive. Please provide only one value.
[2025-03-23T09:03:26.960+0000] {taskinstance.py:1149} INFO - Marking task as FAILED. dag_id=load_csv_to_bq, task_id=load_csv_to_bq, execution_date=20250323T090323, start_date=20250323T090326, end_date=20250323T090326
[2025-03-23T09:03:26.974+0000] {standard_task_runner.py:107} ERROR - Failed to execute job 18 for task load_csv_to_bq (The `keyfile_dict`, `key_path`, and `key_secret_name` fields are all mutually exclusive. Please provide only one value.; 1788)
[2025-03-23T09:03:27.013+0000] {local_task_job_runner.py:234} INFO - Task exited with return code 1
[2025-03-23T09:03:27.030+0000] {taskinstance.py:3309} INFO - 0 downstream tasks scheduled from follow-on schedule check
