[2025-04-05T10:58:35.647+0000] {taskinstance.py:1979} INFO - Dependencies all met for dep_context=non-requeueable deps ti=<TaskInstance: fetch_data_and_upload_to_gcs.download_and_upload_to_gcs manual__2025-04-05T10:58:32.843699+00:00 [queued]>
[2025-04-05T10:58:35.659+0000] {taskinstance.py:1979} INFO - Dependencies all met for dep_context=requeueable deps ti=<TaskInstance: fetch_data_and_upload_to_gcs.download_and_upload_to_gcs manual__2025-04-05T10:58:32.843699+00:00 [queued]>
[2025-04-05T10:58:35.659+0000] {taskinstance.py:2193} INFO - Starting attempt 1 of 1
[2025-04-05T10:58:35.675+0000] {taskinstance.py:2214} INFO - Executing <Task(PythonOperator): download_and_upload_to_gcs> on 2025-04-05 10:58:32.843699+00:00
[2025-04-05T10:58:35.680+0000] {standard_task_runner.py:60} INFO - Started process 208 to run task
[2025-04-05T10:58:35.685+0000] {standard_task_runner.py:87} INFO - Running: ['***', 'tasks', 'run', 'fetch_data_and_upload_to_gcs', 'download_and_upload_to_gcs', 'manual__2025-04-05T10:58:32.843699+00:00', '--job-id', '13', '--raw', '--subdir', 'DAGS_FOLDER/fetch_data_and_upload_to_gcs.py', '--cfg-path', '/tmp/tmp48wb53np']
[2025-04-05T10:58:35.693+0000] {standard_task_runner.py:88} INFO - Job 13: Subtask download_and_upload_to_gcs
[2025-04-05T10:58:35.764+0000] {task_command.py:423} INFO - Running <TaskInstance: fetch_data_and_upload_to_gcs.download_and_upload_to_gcs manual__2025-04-05T10:58:32.843699+00:00 [running]> on host 94ac0235f9be
[2025-04-05T10:58:35.857+0000] {taskinstance.py:2510} INFO - Exporting env vars: AIRFLOW_CTX_DAG_OWNER='***' AIRFLOW_CTX_DAG_ID='fetch_data_and_upload_to_gcs' AIRFLOW_CTX_TASK_ID='download_and_upload_to_gcs' AIRFLOW_CTX_EXECUTION_DATE='2025-04-05T10:58:32.843699+00:00' AIRFLOW_CTX_TRY_NUMBER='1' AIRFLOW_CTX_DAG_RUN_ID='manual__2025-04-05T10:58:32.843699+00:00'
[2025-04-05T10:58:36.392+0000] {connection.py:269} WARNING - Connection schemes (type: google_cloud_platform) shall not contain '_' according to RFC3986.
[2025-04-05T10:58:36.401+0000] {base.py:83} INFO - Using connection ID 'google_cloud_default' for task execution.
[2025-04-05T10:58:36.430+0000] {taskinstance.py:2728} ERROR - Task failed with exception
Traceback (most recent call last):
  File "/home/airflow/.local/lib/python3.10/site-packages/airflow/providers/google/common/hooks/base_google.py", line 268, in get_credentials_and_project_id
    keyfile_dict_json = json.loads(keyfile_dict)
  File "/usr/local/lib/python3.10/json/__init__.py", line 346, in loads
    return _default_decoder.decode(s)
  File "/usr/local/lib/python3.10/json/decoder.py", line 337, in decode
    obj, end = self.raw_decode(s, idx=_w(s, 0).end())
  File "/usr/local/lib/python3.10/json/decoder.py", line 353, in raw_decode
    obj, end = self.scan_once(s, idx)
json.decoder.JSONDecodeError: Unterminated string starting at: line 1 column 153 (char 152)

During handling of the above exception, another exception occurred:

Traceback (most recent call last):
  File "/home/airflow/.local/lib/python3.10/site-packages/airflow/models/taskinstance.py", line 444, in _execute_task
    result = _execute_callable(context=context, **execute_callable_kwargs)
  File "/home/airflow/.local/lib/python3.10/site-packages/airflow/models/taskinstance.py", line 414, in _execute_callable
    return execute_callable(context=context, **execute_callable_kwargs)
  File "/home/airflow/.local/lib/python3.10/site-packages/airflow/operators/python.py", line 200, in execute
    return_value = self.execute_callable()
  File "/home/airflow/.local/lib/python3.10/site-packages/airflow/operators/python.py", line 217, in execute_callable
    return self.python_callable(*self.op_args, **self.op_kwargs)
  File "/opt/airflow/dags/fetch_data_and_upload_to_gcs.py", line 19, in download_and_upload_to_gcs
    hook.upload(bucket_name, destination_blob_name, temp_file.name)
  File "/home/airflow/.local/lib/python3.10/site-packages/airflow/providers/google/cloud/hooks/gcs.py", line 525, in upload
    client = self.get_conn()
  File "/home/airflow/.local/lib/python3.10/site-packages/airflow/providers/google/cloud/hooks/gcs.py", line 168, in get_conn
    credentials=self.get_credentials(), client_info=CLIENT_INFO, project=self.project_id
  File "/home/airflow/.local/lib/python3.10/site-packages/airflow/providers/google/common/hooks/base_google.py", line 307, in get_credentials
    credentials, _ = self.get_credentials_and_project_id()
  File "/home/airflow/.local/lib/python3.10/site-packages/airflow/providers/google/common/hooks/base_google.py", line 270, in get_credentials_and_project_id
    raise AirflowException("Invalid key JSON.")
airflow.exceptions.AirflowException: Invalid key JSON.
[2025-04-05T10:58:36.439+0000] {taskinstance.py:1149} INFO - Marking task as FAILED. dag_id=fetch_data_and_upload_to_gcs, task_id=download_and_upload_to_gcs, execution_date=20250405T105832, start_date=20250405T105835, end_date=20250405T105836
[2025-04-05T10:58:36.495+0000] {standard_task_runner.py:107} ERROR - Failed to execute job 13 for task download_and_upload_to_gcs (Invalid key JSON.; 208)
[2025-04-05T10:58:36.550+0000] {local_task_job_runner.py:234} INFO - Task exited with return code 1
[2025-04-05T10:58:36.619+0000] {taskinstance.py:3309} INFO - 0 downstream tasks scheduled from follow-on schedule check
