[2025-03-24T09:22:34.340+0000] {taskinstance.py:1979} INFO - Dependencies all met for dep_context=non-requeueable deps ti=<TaskInstance: test_fetch_url_csv.fetch_and_log_csv_urls manual__2025-03-24T09:22:32.782599+00:00 [queued]>
[2025-03-24T09:22:34.347+0000] {taskinstance.py:1979} INFO - Dependencies all met for dep_context=requeueable deps ti=<TaskInstance: test_fetch_url_csv.fetch_and_log_csv_urls manual__2025-03-24T09:22:32.782599+00:00 [queued]>
[2025-03-24T09:22:34.347+0000] {taskinstance.py:2193} INFO - Starting attempt 1 of 1
[2025-03-24T09:22:34.361+0000] {taskinstance.py:2214} INFO - Executing <Task(PythonOperator): fetch_and_log_csv_urls> on 2025-03-24 09:22:32.782599+00:00
[2025-03-24T09:22:34.365+0000] {standard_task_runner.py:60} INFO - Started process 1447 to run task
[2025-03-24T09:22:34.368+0000] {standard_task_runner.py:87} INFO - Running: ['***', 'tasks', 'run', 'test_fetch_url_csv', 'fetch_and_log_csv_urls', 'manual__2025-03-24T09:22:32.782599+00:00', '--job-id', '112', '--raw', '--subdir', 'DAGS_FOLDER/test_fetch_url_csv.py', '--cfg-path', '/tmp/tmpp_b_jixb']
[2025-03-24T09:22:34.370+0000] {standard_task_runner.py:88} INFO - Job 112: Subtask fetch_and_log_csv_urls
[2025-03-24T09:22:34.416+0000] {task_command.py:423} INFO - Running <TaskInstance: test_fetch_url_csv.fetch_and_log_csv_urls manual__2025-03-24T09:22:32.782599+00:00 [running]> on host 3d764bfd33f3
[2025-03-24T09:22:34.487+0000] {taskinstance.py:2510} INFO - Exporting env vars: AIRFLOW_CTX_DAG_OWNER='***' AIRFLOW_CTX_DAG_ID='test_fetch_url_csv' AIRFLOW_CTX_TASK_ID='fetch_and_log_csv_urls' AIRFLOW_CTX_EXECUTION_DATE='2025-03-24T09:22:32.782599+00:00' AIRFLOW_CTX_TRY_NUMBER='1' AIRFLOW_CTX_DAG_RUN_ID='manual__2025-03-24T09:22:32.782599+00:00'
[2025-03-24T09:22:35.530+0000] {taskinstance.py:2728} ERROR - Task failed with exception
Traceback (most recent call last):
  File "/home/airflow/.local/lib/python3.8/site-packages/airflow/models/taskinstance.py", line 444, in _execute_task
    result = _execute_callable(context=context, **execute_callable_kwargs)
  File "/home/airflow/.local/lib/python3.8/site-packages/airflow/models/taskinstance.py", line 414, in _execute_callable
    return execute_callable(context=context, **execute_callable_kwargs)
  File "/home/airflow/.local/lib/python3.8/site-packages/airflow/operators/python.py", line 200, in execute
    return_value = self.execute_callable()
  File "/home/airflow/.local/lib/python3.8/site-packages/airflow/operators/python.py", line 217, in execute_callable
    return self.python_callable(*self.op_args, **self.op_kwargs)
  File "/opt/airflow/dags/test_fetch_url_csv.py", line 50, in fetch_and_log_csv_urls
    csv_urls = get_csv_urls_from_website_using_td(base_url, subdirectory_url)
  File "/opt/airflow/dags/test_fetch_url_csv.py", line 37, in get_csv_urls_from_website_using_td
    raise Exception(f"Failed to fetch the website. Status code: {response.status_code}")
Exception: Failed to fetch the website. Status code: 404
[2025-03-24T09:22:35.539+0000] {taskinstance.py:1149} INFO - Marking task as FAILED. dag_id=test_fetch_url_csv, task_id=fetch_and_log_csv_urls, execution_date=20250324T092232, start_date=20250324T092234, end_date=20250324T092235
[2025-03-24T09:22:35.552+0000] {standard_task_runner.py:107} ERROR - Failed to execute job 112 for task fetch_and_log_csv_urls (Failed to fetch the website. Status code: 404; 1447)
[2025-03-24T09:22:35.567+0000] {local_task_job_runner.py:234} INFO - Task exited with return code 1
[2025-03-24T09:22:35.581+0000] {taskinstance.py:3309} INFO - 0 downstream tasks scheduled from follow-on schedule check
