[2025-03-24T11:57:55.997+0000] {taskinstance.py:1979} INFO - Dependencies all met for dep_context=non-requeueable deps ti=<TaskInstance: fetch_filtered_data_and_upload_to_gcs.fetch_and_upload_2023_W1_spring-Inner-Part1.csv manual__2025-03-24T11:57:52.705755+00:00 [queued]>
[2025-03-24T11:57:56.021+0000] {taskinstance.py:1979} INFO - Dependencies all met for dep_context=requeueable deps ti=<TaskInstance: fetch_filtered_data_and_upload_to_gcs.fetch_and_upload_2023_W1_spring-Inner-Part1.csv manual__2025-03-24T11:57:52.705755+00:00 [queued]>
[2025-03-24T11:57:56.022+0000] {taskinstance.py:2193} INFO - Starting attempt 1 of 1
[2025-03-24T11:57:56.051+0000] {taskinstance.py:2214} INFO - Executing <Task(PythonOperator): fetch_and_upload_2023_W1_spring-Inner-Part1.csv> on 2025-03-24 11:57:52.705755+00:00
[2025-03-24T11:57:56.058+0000] {standard_task_runner.py:60} INFO - Started process 4173 to run task
[2025-03-24T11:57:56.069+0000] {standard_task_runner.py:87} INFO - Running: ['***', 'tasks', 'run', 'fetch_filtered_data_and_upload_to_gcs', 'fetch_and_upload_2023_W1_spring-Inner-Part1.csv', 'manual__2025-03-24T11:57:52.705755+00:00', '--job-id', '172', '--raw', '--subdir', 'DAGS_FOLDER/step_one.py', '--cfg-path', '/tmp/tmpgmap_6aj']
[2025-03-24T11:57:56.077+0000] {standard_task_runner.py:88} INFO - Job 172: Subtask fetch_and_upload_2023_W1_spring-Inner-Part1.csv
[2025-03-24T11:57:56.186+0000] {task_command.py:423} INFO - Running <TaskInstance: fetch_filtered_data_and_upload_to_gcs.fetch_and_upload_2023_W1_spring-Inner-Part1.csv manual__2025-03-24T11:57:52.705755+00:00 [running]> on host 3d764bfd33f3
[2025-03-24T11:57:56.406+0000] {taskinstance.py:2510} INFO - Exporting env vars: AIRFLOW_CTX_DAG_OWNER='***' AIRFLOW_CTX_DAG_ID='fetch_filtered_data_and_upload_to_gcs' AIRFLOW_CTX_TASK_ID='fetch_and_upload_2023_W1_spring-Inner-Part1.csv' AIRFLOW_CTX_EXECUTION_DATE='2025-03-24T11:57:52.705755+00:00' AIRFLOW_CTX_TRY_NUMBER='1' AIRFLOW_CTX_DAG_RUN_ID='manual__2025-03-24T11:57:52.705755+00:00'
[2025-03-24T11:57:56.413+0000] {logging_mixin.py:188} INFO - Fetching URL: https://cycling.data.tfl.gov.uk/ActiveTravelCountsProgramme/2023%20W1%20spring-Inner-Part1.csv
[2025-03-24T11:57:59.064+0000] {logging_mixin.py:188} INFO - Cleaned filename: 2023_W1_spring-Inner-Part1.csv
[2025-03-24T11:57:59.065+0000] {logging_mixin.py:188} INFO - GCS path: cycling_data/2023_W1_spring-Inner-Part1.csv_20250324115759.csv
[2025-03-24T12:00:15.676+0000] {taskinstance.py:2728} ERROR - Task failed with exception
Traceback (most recent call last):
  File "/home/airflow/.local/lib/python3.8/site-packages/urllib3/connectionpool.py", line 715, in urlopen
    httplib_response = self._make_request(
  File "/home/airflow/.local/lib/python3.8/site-packages/urllib3/connectionpool.py", line 416, in _make_request
    conn.request(method, url, **httplib_request_kw)
  File "/home/airflow/.local/lib/python3.8/site-packages/urllib3/connection.py", line 244, in request
    super(HTTPConnection, self).request(method, url, body=body, headers=headers)
  File "/usr/local/lib/python3.8/http/client.py", line 1256, in request
    self._send_request(method, url, body, headers, encode_chunked)
  File "/usr/local/lib/python3.8/http/client.py", line 1302, in _send_request
    self.endheaders(body, encode_chunked=encode_chunked)
  File "/usr/local/lib/python3.8/http/client.py", line 1251, in endheaders
    self._send_output(message_body, encode_chunked=encode_chunked)
  File "/usr/local/lib/python3.8/http/client.py", line 1050, in _send_output
    self.send(chunk)
  File "/usr/local/lib/python3.8/http/client.py", line 972, in send
    self.sock.sendall(data)
  File "/usr/local/lib/python3.8/ssl.py", line 1237, in sendall
    v = self.send(byte_view[count:])
  File "/usr/local/lib/python3.8/ssl.py", line 1206, in send
    return self._sslobj.write(data)
socket.timeout: The write operation timed out

During handling of the above exception, another exception occurred:

Traceback (most recent call last):
  File "/home/airflow/.local/lib/python3.8/site-packages/requests/adapters.py", line 486, in send
    resp = conn.urlopen(
  File "/home/airflow/.local/lib/python3.8/site-packages/urllib3/connectionpool.py", line 799, in urlopen
    retries = retries.increment(
  File "/home/airflow/.local/lib/python3.8/site-packages/urllib3/util/retry.py", line 550, in increment
    raise six.reraise(type(error), error, _stacktrace)
  File "/home/airflow/.local/lib/python3.8/site-packages/urllib3/packages/six.py", line 769, in reraise
    raise value.with_traceback(tb)
  File "/home/airflow/.local/lib/python3.8/site-packages/urllib3/connectionpool.py", line 715, in urlopen
    httplib_response = self._make_request(
  File "/home/airflow/.local/lib/python3.8/site-packages/urllib3/connectionpool.py", line 416, in _make_request
    conn.request(method, url, **httplib_request_kw)
  File "/home/airflow/.local/lib/python3.8/site-packages/urllib3/connection.py", line 244, in request
    super(HTTPConnection, self).request(method, url, body=body, headers=headers)
  File "/usr/local/lib/python3.8/http/client.py", line 1256, in request
    self._send_request(method, url, body, headers, encode_chunked)
  File "/usr/local/lib/python3.8/http/client.py", line 1302, in _send_request
    self.endheaders(body, encode_chunked=encode_chunked)
  File "/usr/local/lib/python3.8/http/client.py", line 1251, in endheaders
    self._send_output(message_body, encode_chunked=encode_chunked)
  File "/usr/local/lib/python3.8/http/client.py", line 1050, in _send_output
    self.send(chunk)
  File "/usr/local/lib/python3.8/http/client.py", line 972, in send
    self.sock.sendall(data)
  File "/usr/local/lib/python3.8/ssl.py", line 1237, in sendall
    v = self.send(byte_view[count:])
  File "/usr/local/lib/python3.8/ssl.py", line 1206, in send
    return self._sslobj.write(data)
urllib3.exceptions.ProtocolError: ('Connection aborted.', timeout('The write operation timed out'))

During handling of the above exception, another exception occurred:

Traceback (most recent call last):
  File "/opt/airflow/dags/step_one.py", line 63, in fetch_and_upload_to_gcs
    gcs_file.write(chunk)
  File "/home/airflow/.local/lib/python3.8/site-packages/google/cloud/storage/fileio.py", line 357, in write
    self._upload_chunks_from_buffer(num_chunks)
  File "/home/airflow/.local/lib/python3.8/site-packages/google/cloud/storage/fileio.py", line 417, in _upload_chunks_from_buffer
    upload.transmit_next_chunk(transport, **kwargs)
  File "/home/airflow/.local/lib/python3.8/site-packages/google/resumable_media/requests/upload.py", line 515, in transmit_next_chunk
    return _request_helpers.wait_and_retry(
  File "/home/airflow/.local/lib/python3.8/site-packages/google/resumable_media/requests/_request_helpers.py", line 178, in wait_and_retry
    raise error
  File "/home/airflow/.local/lib/python3.8/site-packages/google/resumable_media/requests/_request_helpers.py", line 155, in wait_and_retry
    response = func()
  File "/home/airflow/.local/lib/python3.8/site-packages/google/resumable_media/requests/upload.py", line 507, in retriable_request
    result = transport.request(
  File "/home/airflow/.local/lib/python3.8/site-packages/google/auth/transport/requests.py", line 541, in request
    response = super(AuthorizedSession, self).request(
  File "/home/airflow/.local/lib/python3.8/site-packages/requests/sessions.py", line 589, in request
    resp = self.send(prep, **send_kwargs)
  File "/home/airflow/.local/lib/python3.8/site-packages/requests/sessions.py", line 703, in send
    r = adapter.send(request, **kwargs)
  File "/home/airflow/.local/lib/python3.8/site-packages/requests/adapters.py", line 501, in send
    raise ConnectionError(err, request=request)
requests.exceptions.ConnectionError: ('Connection aborted.', timeout('The write operation timed out'))

During handling of the above exception, another exception occurred:

Traceback (most recent call last):
  File "/home/airflow/.local/lib/python3.8/site-packages/airflow/models/taskinstance.py", line 444, in _execute_task
    result = _execute_callable(context=context, **execute_callable_kwargs)
  File "/home/airflow/.local/lib/python3.8/site-packages/airflow/models/taskinstance.py", line 414, in _execute_callable
    return execute_callable(context=context, **execute_callable_kwargs)
  File "/home/airflow/.local/lib/python3.8/site-packages/airflow/operators/python.py", line 200, in execute
    return_value = self.execute_callable()
  File "/home/airflow/.local/lib/python3.8/site-packages/airflow/operators/python.py", line 217, in execute_callable
    return self.python_callable(*self.op_args, **self.op_kwargs)
  File "/opt/airflow/dags/step_one.py", line 63, in fetch_and_upload_to_gcs
    gcs_file.write(chunk)
  File "/home/airflow/.local/lib/python3.8/site-packages/google/cloud/storage/fileio.py", line 437, in close
    self._upload_chunks_from_buffer(1)
  File "/home/airflow/.local/lib/python3.8/site-packages/google/cloud/storage/fileio.py", line 417, in _upload_chunks_from_buffer
    upload.transmit_next_chunk(transport, **kwargs)
  File "/home/airflow/.local/lib/python3.8/site-packages/google/resumable_media/requests/upload.py", line 503, in transmit_next_chunk
    method, url, payload, headers = self._prepare_request()
  File "/home/airflow/.local/lib/python3.8/site-packages/google/resumable_media/_upload.py", line 627, in _prepare_request
    raise ValueError(msg)
ValueError: Bytes stream is in unexpected state. The local stream has had 41943040 bytes read from it while 0 bytes have already been updated (they should match).
[2025-03-24T12:00:15.706+0000] {taskinstance.py:1149} INFO - Marking task as FAILED. dag_id=fetch_filtered_data_and_upload_to_gcs, task_id=fetch_and_upload_2023_W1_spring-Inner-Part1.csv, execution_date=20250324T115752, start_date=20250324T115755, end_date=20250324T120015
[2025-03-24T12:00:15.729+0000] {standard_task_runner.py:107} ERROR - Failed to execute job 172 for task fetch_and_upload_2023_W1_spring-Inner-Part1.csv (Bytes stream is in unexpected state. The local stream has had 41943040 bytes read from it while 0 bytes have already been updated (they should match).; 4173)
[2025-03-24T12:00:15.766+0000] {local_task_job_runner.py:234} INFO - Task exited with return code 1
[2025-03-24T12:00:15.783+0000] {taskinstance.py:3309} INFO - 0 downstream tasks scheduled from follow-on schedule check
