[2025-03-23T08:55:35.243+0000] {taskinstance.py:1979} INFO - Dependencies all met for dep_context=non-requeueable deps ti=<TaskInstance: load_csv_to_bq.load_csv_to_bq manual__2025-03-23T08:55:27.552079+00:00 [queued]>
[2025-03-23T08:55:35.256+0000] {taskinstance.py:1979} INFO - Dependencies all met for dep_context=requeueable deps ti=<TaskInstance: load_csv_to_bq.load_csv_to_bq manual__2025-03-23T08:55:27.552079+00:00 [queued]>
[2025-03-23T08:55:35.256+0000] {taskinstance.py:2193} INFO - Starting attempt 1 of 1
[2025-03-23T08:55:35.275+0000] {taskinstance.py:2214} INFO - Executing <Task(GCSToBigQueryOperator): load_csv_to_bq> on 2025-03-23 08:55:27.552079+00:00
[2025-03-23T08:55:35.280+0000] {standard_task_runner.py:60} INFO - Started process 1668 to run task
[2025-03-23T08:55:35.287+0000] {standard_task_runner.py:87} INFO - Running: ['***', 'tasks', 'run', 'load_csv_to_bq', 'load_csv_to_bq', 'manual__2025-03-23T08:55:27.552079+00:00', '--job-id', '15', '--raw', '--subdir', 'DAGS_FOLDER/load_csv_to_bq.py', '--cfg-path', '/tmp/tmp66odetap']
[2025-03-23T08:55:35.288+0000] {standard_task_runner.py:88} INFO - Job 15: Subtask load_csv_to_bq
[2025-03-23T08:55:35.355+0000] {task_command.py:423} INFO - Running <TaskInstance: load_csv_to_bq.load_csv_to_bq manual__2025-03-23T08:55:27.552079+00:00 [running]> on host c0ff61c5806f
[2025-03-23T08:55:35.478+0000] {taskinstance.py:2510} INFO - Exporting env vars: AIRFLOW_CTX_DAG_OWNER='***' AIRFLOW_CTX_DAG_ID='load_csv_to_bq' AIRFLOW_CTX_TASK_ID='load_csv_to_bq' AIRFLOW_CTX_EXECUTION_DATE='2025-03-23T08:55:27.552079+00:00' AIRFLOW_CTX_TRY_NUMBER='1' AIRFLOW_CTX_DAG_RUN_ID='manual__2025-03-23T08:55:27.552079+00:00'
[2025-03-23T08:55:35.493+0000] {connection.py:269} WARNING - Connection schemes (type: google_cloud_platform) shall not contain '_' according to RFC3986.
[2025-03-23T08:55:35.501+0000] {base.py:83} INFO - Using connection ID 'google_cloud_default' for task execution.
[2025-03-23T08:55:35.503+0000] {gcs_to_bigquery.py:379} INFO - Using existing BigQuery table for storing data...
[2025-03-23T08:55:35.516+0000] {taskinstance.py:2728} ERROR - Task failed with exception
Traceback (most recent call last):
  File "/home/airflow/.local/lib/python3.8/site-packages/airflow/providers/google/common/hooks/base_google.py", line 268, in get_credentials_and_project_id
    keyfile_dict_json = json.loads(keyfile_dict)
  File "/usr/local/lib/python3.8/json/__init__.py", line 357, in loads
    return _default_decoder.decode(s)
  File "/usr/local/lib/python3.8/json/decoder.py", line 337, in decode
    obj, end = self.raw_decode(s, idx=_w(s, 0).end())
  File "/usr/local/lib/python3.8/json/decoder.py", line 353, in raw_decode
    obj, end = self.scan_once(s, idx)
json.decoder.JSONDecodeError: Unterminated string starting at: line 1 column 153 (char 152)

During handling of the above exception, another exception occurred:

Traceback (most recent call last):
  File "/home/airflow/.local/lib/python3.8/site-packages/airflow/models/taskinstance.py", line 444, in _execute_task
    result = _execute_callable(context=context, **execute_callable_kwargs)
  File "/home/airflow/.local/lib/python3.8/site-packages/airflow/models/taskinstance.py", line 414, in _execute_callable
    return execute_callable(context=context, **execute_callable_kwargs)
  File "/home/airflow/.local/lib/python3.8/site-packages/airflow/providers/google/cloud/transfers/gcs_to_bigquery.py", line 380, in execute
    self.configuration = self._use_existing_table()
  File "/home/airflow/.local/lib/python3.8/site-packages/airflow/providers/google/cloud/transfers/gcs_to_bigquery.py", line 582, in _use_existing_table
    default_project_id=self.hook.project_id,
  File "/home/airflow/.local/lib/python3.8/site-packages/airflow/providers/google/common/hooks/base_google.py", line 372, in project_id
    _, project_id = self.get_credentials_and_project_id()
  File "/home/airflow/.local/lib/python3.8/site-packages/airflow/providers/google/common/hooks/base_google.py", line 270, in get_credentials_and_project_id
    raise AirflowException("Invalid key JSON.")
airflow.exceptions.AirflowException: Invalid key JSON.
[2025-03-23T08:55:35.522+0000] {taskinstance.py:1149} INFO - Marking task as FAILED. dag_id=load_csv_to_bq, task_id=load_csv_to_bq, execution_date=20250323T085527, start_date=20250323T085535, end_date=20250323T085535
[2025-03-23T08:55:35.548+0000] {standard_task_runner.py:107} ERROR - Failed to execute job 15 for task load_csv_to_bq (Invalid key JSON.; 1668)
[2025-03-23T08:55:35.580+0000] {local_task_job_runner.py:234} INFO - Task exited with return code 1
[2025-03-23T08:55:35.604+0000] {taskinstance.py:3309} INFO - 0 downstream tasks scheduled from follow-on schedule check
